## 10.1 'try..catch'와 에러 핸들링

에러가 발생하면 스크립트는 ‘죽고’(즉시 중단되고), 콘솔에 에러가 출력된다.

그러나 `try..catch` 문법을 사용하면 스크립트가 죽는 걸 방지하고, 에러를 ‘잡아서(catch)’ 더 합당한 무언가를 할 수 있다.



### `try…catch` 문법

```js
try {

  // 시도할 코드...

} catch (err) {

  // 에러 핸들링

}
```

`try` 블록에서 에러가 발생해도 `catch` 블록에서 에러를 처리하기 때문에 스크립트가 죽지 않는다.

- `try…catch` 동작 알고리즘

1. 먼저, `try {...}` 안의 코드가 실행된다.
2. 에러가 없다면, `try` 안의 마지막 줄까지 실행되고, `catch` 블록은 건너뛴다.
3. 에러가 있다면, `try` 안 코드의 실행이 중단되고, `catch(err)` 블록으로 제어 흐름이 넘어간다. 변수 `err`(아무 이름이나 사용 가능)는 무슨 일이 일어났는지에 대한 설명이 담긴 에러 객체를 포함한다.



> ***`try..catch`는 오직 런타임 에러에만 동작한다.***
>
> `try..catch` 는 실행 가능한 코드에서만 동작한다. 
>
> 실행 가능한 코드는 유효한 자바스크립트 코드를 의미한다.
>
> 문법적으로 잘못된 경우에는 `try..catch` 가 동작하지 않는다.
>
> 자바스크립트 엔진은 코드를 읽고 난 후 코드를 실행한다. 코드를 읽는 중에 발생하는 에러는 **parse-time 에러** 라고 하는데, 엔진은 이 코드를 이해할 수 없기 때문에 **parse-time 에러** 는 코드 안에서 복구가 불가능하다.
>
> **런타임에러** 는 유효한 코드에서 발생하는 에러를 말하고 **런타임에러**에서만 `try..catch` 로 처리할 수 있다.



> ***`try..catch`는 동기적으로 동작한다.***
>
> setTimeout처럼 ‘스케줄 된(scheduled)’ 코드에서 발생한 예외는 `try..catch`에서 잡아낼 수 없다.
>
> ```js
> // 잘못
> try {
>   setTimeout(function() {
>     noSuchVariable; // 스크립트는 콜백함수 내에서 죽는다.
>   }, 1000);
> } catch (e) {
>   alert( "작동 멈춤" );
> }
> 
> // 올바른
> setTimeout(function() {
>   try {
>     noSuchVariable; // 이제 try..catch에서 에러를 핸들링 할 수 있습니다!
>   } catch {
>     alert( "에러를 잡았습니다!" );
>   }
> }, 1000);
> ```
>
> `setTimeout`에 넘겨진 익명 함수는 엔진이 `try..catch`를 떠난 다음에서야 실행되기 때문에 반드시 콜백함수 내부에 구현해야한다.



### 에러객체

in `try catch`

`try` 블록에서 에러가 발생하면 에러 상세내용이 담긴 객체를 생성한다.

그 후 `catch` 블록에 이 에러객체를 인수로 전달한다.

```js
try {
  ...
} catch(err) { // try에서 생성된 에러객체를 catch문에서 err로 사용
  ...
}
```



**에러객체의 주요 프로퍼티**

- `name` : 에러 이름
- `message` : 에러 상세 내용을 담고 있는 문자 메시지
- `stack` (표준아님) : 현재 호출 스택, 에러를 유발한 중첩 호출들의 순서  정보를 가진 문자열. (디버깅 목적으로 사용)

```js
try {
  lalala;
} catch (err) {
  console.log(err); // ReferenceError: lalala is not defined ...
  console.log(err.name); // ReferenceError
  console.log(err.message); // lalala is not defined
  console.log(err.stack); // ReferenceError: lalala is not defined ...
}
```



### 선택적 `catch` 바인딩

> 최근에 추가된 문법

에러에 대한 자세한 정보가 필요하지 않으면,  

아래와 같이 에러 객체를  `catch` 에서 생략이 가능하다.

```js
try {
  // ...
} catch { // <-- (err) 없이 쓸 수 있음
  // ...
}
```



### `try...catch` 사용하기 (활용예제)

##### 서버로부터 전달받은 데이터 처리 (feet. `JSON.parse(json)`)

```js
let json = "{ bad json }";

try {

  let user = JSON.parse(json); // <-- 여기서 에러가 발생하므로
  alert( user.name ); // 이 코드는 동작하지 않습니다.

} catch (e) {
  // 에러가 발생하면 제어 흐름이 catch 문으로 넘어옵니다.
  alert( "데이터에 에러가 있어 재요청을 시도합니다." );
  alert( e.name );
  alert( e.message );
}
```

**잘못된 형식의 `json`이 들어온 경우, `JSON.parse`는 에러를 만들기 때문에 스크립트가 ‘죽는다’.**

이런 경우를 대비하여 `try...catch` 문을 활용해서 잘못된 형식의 json이 들어왔을 때 스크립트가 죽지않게하고 예외처리를 하도록 활용할 수 있다.



### 직접 에러를 만들어서 던지기 `throw`

```js
const json = '{ "age": 30 }'; // 불완전한 데이터

try {
  const user = JSON.parse(json); // <-- 에러 없음
  console.log(user.name); // undefined, 에러는 아니다.
} catch (e) {
  console.log('실행되지 않습니다.');
}
```

`json`이 문법적으로 잘못되진 않았지만, 스크립트 내에서 프로퍼티 `name`을 가지고 있지 않다면 에러가 아니기 때문에 `catch` 문에 도달하지 않는다.

**따라서 문법적인 에러가 아닌 경우지만 예외처리를 해야할 경우 직접 에러를 만들수 활용할 수 있다**

직접 에러를 만드는 방법은 아래에 나오는 `throw` 연산자를 이용하면 된다.



### `throw` 연산자

```js
throw <에러 객체>
```

이론적으로 원시형을 포함한 어떤 것이든 에러객체로 사용할 수 있다.

에러객체로써 사용할 때 내장에러와 호환성을 위해 `name` 과 `message` 프로퍼티를 넣어주는것을 권장한다.



##### 표준 에러 객체

자바스크립트에서는 아래와 같은 표준 에러 객체 생성자를 지원한다.

이 생성자들을 이용해서 에러 객체를 만든다.

```js
let error = new Error(message); // 범용적인(?) 에러
let error = new SyntaxError(message); // 문법 에러
let error = new ReferenceError(message); // 참조 에러
// ...

// 예시 //
const error = new Error('이건 잘못된 일이야');

console.log(error); // Error: 이건 잘못된 일이야... stack...
console.log(error.name); // Error
console.log(error.message); // 이건 잘못된 일이야
```

표준 에러 객체의 `name` 은 생성자 이름과 동일한 값을 갖고, 프로퍼티 값을 `message` 로 한다.



다시 위의 예제에서 직접 에러 객체를 생성해보자

```js
const json = '{ "age": 30 }'; // 불완전한 데이터

try {
  const user = JSON.parse(json); // <-- 에러 없음
  
  if (!user.name) {
    throw new SyntaxError('불완전한 데이터: 이름 없음');
  }
  
  console.log(user.name); // undefined, 에러는 아니다.
} catch (e) {
  console.log(`JSON Error: ` + e.message);
}
// JSON Error: 불완전한 데이터: 이름 없음
```



### 에러 다시 던지기

`try` 블록 안에서 다양한 에러가 발생할 수 있다.

하지만 여태 우리가 했던 내용으로는 `catch` 블록에서는 처음 발생한 에러를 캐치하여 처리한다.

때문에 다양한 에러를 처리를 할 필요성이 있다.

즉, `try` 블록에서 발생하는 모든 에러를 잡기 위해 "에러 다시 던지기" 기법을 사용하면된다.

> **catch는 알고 있는 에러만 처리하고 나머지는 ‘다시 던져야’ 합니다.**



**‘다시 던지기’ 기술**

1. catch가 모든 에러를 받는다.
2. `catch(err) {...}` 블록 안에서 에러 객체 `err`를 분석한다.
3. 에러 처리 방법을 알지 못하면 `throw err`를 한다.

(보통 에러 타입을 `instanceof` 명령어로 체크한다.)



```js
function readData() {
  const json = '{ "age": 30 }'; // 불완전한 데이터

  try {
    const user = JSON.parse(json); // <-- 에러 없음

    blab(); // 예상치 못한 에러

    if (!user.name) {
      throw new SyntaxError('불완전한 데이터: 이름 없음');
    }

    console.log(user.name); // undefined, 에러는 아니다.
  } catch (err) {
    if (err instanceof SyntaxError) {
      console.log('SytaxError 발생!');
      return;
    }

    throw err; // 예상치 못한 에러는 에러 다시 던지기!
  }
}

try {
  readData();
} catch (err) {
  console.log('External catch got: ' + err);
}
// External catch got: ReferenceError: blab is not defined
```

예상치 못한 에러가 있다면 `catch` 블록에서 다시  `throw err` 를 해줌으로 써 외부에 에러를 뱉어낸다.

이때 바깥에 `try...catch` 문이 있다면 여기서 에러를 잡아준다. 

만야 바깥에 `try...catch` 문이 없다면 스크립트는 죽는다.

이렇게 하면 `catch` 블록에선 어떻게 다룰지 알고 있는 에러만 처리하고, 알 수 없는 에러는 ‘건너뛸 수’ 있다.



### try...catch...finally

```js
try {
   ... 코드를 실행 ...
} catch(e) {
   ... 에러 핸들링 ...
} finally {
   ... 항상 실행 ...
}
```

`try...catch` 문에 `finally` 라는 코드 절을 하나 더 가질수 있다.

`finally` 는 무조건 항상 실행되는 절이다.

- 에러가 없는 경우: `try` 실행이 끝난 후
- 에러가 있는 경우: `catch` 실행이 끝난 후

`finally` 절은 무언가를 실행하고, 실행 결과에 상관없이 실행을 완료하고 싶을 경우 사용된다.



##### 활용예시 - 피보나치 함수

만약 피보나치 함수의 연산시간을 측정한다하자.

그런데 피보나치 함수의 실행 도중 에러가 발생할 경우에도 함수의 연산시간을 측정하고싶다면

`finally` 절에서 처리하면된다.

```js
let num = +prompt("양의 정수를 입력해주세요.", 35)

let diff, result;

function fib(n) {
  if (n < 0 || Math.trunc(n) != n) {
    throw new Error("음수나 정수가 아닌 값은 처리할 수 없습니다.");
  }
  return n <= 1 ? n : fib(n - 1) + fib(n - 2);
}

let start = Date.now();

try {
  result = fib(num);
} catch (e) {
  result = 0;
} finally {
  diff = Date.now() - start;
}

alert(result || "에러 발생");

alert( `연산 시간: ${diff}ms` );
```



> - `try..catch..finally` 문은 블록이기 때문에, 안의 변수는 지역 변수이다.
>
> - `finally` 절은 `try..catch` 절을 빠져나가는 *어떤* 경우에도 실행된다. `return`을 사용해 명시적으로 빠져나가려는 경우도 마찬가지다.
> - `catch` 절이 없는 `try..finally` 구문은 매우 유용하게 사용할 수있다. 따로 에러처리는 필요하지 않지만 스크립트가 죽었을 때 처리하는 일을 `finally` 에서 명시할 수 있다.
>
> ```js
> function func() {
>   // 무언가를 측정하는 경우와 같이 끝맺음이 있어야 하는 프로세스
>   try {
>     // ...
>   } finally {
>     // 스크립트가 죽더라도 완료됨
>   }
> }
> ```

