# 10-01'try..catch'와 에러 핸들링

## `try...catch'문법

``` jsx
try{
    // 코드...
}catch(err){
    // 에러 핸들링
}
```

ex) 에러가 없는 경우 
``` jsx
try {

    console.log('try 블록 시작');  // (1) <--
  
    // ...에러가 없습니다.
  
    console.log('try 블록 끝');   // (2) <--
  
  } catch(err) {
  
    console.log('에러가 없으므로, catch는 무시됩니다.'); // (3)
  
  }
  ```

ex) 에러가 있는 경우
``` jsx
try {

    console.log('try 블록 시작');  // (1) <--
  
    lalala; // 에러, 변수가 정의되지 않음!
  
    console.log('try 블록 끝(절대 도달하지 않음)');   // (2) <--
  
  } catch(err) {
  
    console.log('에러가 발생했습니다!'); // (3)
  
  }
```

- try..catch는 오직 런타임 에러에만 동작한다. 
- try..catch는 동기적으로 동작한다. (setTimeout 같은 비동기는 못 잡는다. )

스케줄 된 함수 내부의 예외를 잡으려면, try..catch를 반드시 함수 내부에 구현해야 합니다.
``` jsx
setTimeout(function() {
  try {
    noSuchVariable; // 이제 try..catch에서 에러를 핸들링 할 수 있습니다!
  } catch {
    alert( "에러를 잡았습니다!" );
  }
}, 1000);
```


## 에러객체 
에러가 발생하면 자바스크립트는 에러 상세 내용이 담긴 객체를 생성한다. 

그 후, catch 블록에 이 객체를 인수로 전달한다. 

``` jsx
try {
  // ...
} catch(err) { // <-- '에러 객체', err 대신 다른 이름으로도 쓸 수 있음
  // ...
}
```

내장 에러 전체와 에러 객체는 두 가지 주요 프로퍼티를 가집니다.

- name: 에러 이름. 정의되지 않은 변수 때문에 발생한 에러라면 "ReferenceError"가 이름이 됩니다.

- message: 에러 상세 내용을 담고 있는 문자 메시지
표준은 아니지만, name과 message 이외에 대부분의 호스트 환경에서 지원하는 프로퍼티도 있습니다. stack은 가장 널리 사용되는 비표준 프로퍼티 중 하나입니다.

- stack: 현재 호출 스택. 에러를 유발한 중첩 호출들의 순서 정보를 가진 문자열로 디버깅 목적으로 사용됩니다.

``` jsx
try {
  lalala; // 에러, 변수가 정의되지 않음!
} catch(err) {
  alert(err.name); // ReferenceError
  alert(err.message); // lalala is not defined
  alert(err.stack); // ReferenceError: lalala is not defined at ... (호출 스택)

  // 에러 전체를 보여줄 수도 있습니다.
  // 이때, 에러 객체는 "name: message" 형태의 문자열로 변환됩니다.
  alert(err); // ReferenceError: lalala is not defined
}
```

## 선택적 'catch' 바인딩
애러에 대한 자세한 정보가 필요하지 않으면, catch에서 이를 생략할 수 있다. 

``` jsx
try{
    //...
}catch{// <--(err) 없이 쓸 수 있다. 
    //..
}
```
## 'try...catch' 사용하기 
``` jsx
let json = '{"name":"John", "age": 30}'; // 서버로부터 전달받은 데이터

let user = JSON.parse(json); // 전달받은 문자열을 자바스크립트 객체로 변환

console.log(user); //{ name: 'John', age: 30 }
// 문자열 형태로 전달받은 user가 프로퍼티를 가진 객체가 됨
console.log( user.name ); // John
console.log( user.age );  // 3
```

만약 서버에서 JSON을 가져올때, 잘못된 json이 들어오면, JSON.parse는 에러를 만들기 때문에 스크립트가 죽는다.

``` jsx
let json = "{ bad json }";

try {

  let user = JSON.parse(json); // <-- 여기서 에러가 발생하므로
  alert( user.name ); // 이 코드는 동작하지 않습니다.

} catch (e) {
  // 에러가 발생하면 제어 흐름이 catch 문으로 넘어옵니다.
  alert( "데이터에 에러가 있어 재요청을 시도합니다." );
  alert( e.name );
  alert( e.message );
}
```

## 직접 에러를 만들어서 던지기 
만약 json은 문법적으로 맞지만 필수 프로퍼티가 없다. 

``` jsx
let json = '{ "age": 30 }'; // 불완전한 데이터

try {

  let user = JSON.parse(json); // <-- 에러 없음
  alert( user.name ); // 이름이 없습니다! <== 여기서 에러를 일부로 유발해봄

} catch (e) {
  alert( "실행되지 않습니다." );
}
```

## 'trow'연산자
기본 문법
``` jsx
throw <error object>
```

에러 만들기 
``` jsx
let json = '{ "age": 30 }'; // 불완전한 데이터

try {

  let user = JSON.parse(json); // <-- 에러 없음

  if (!user.name) {
    throw new SyntaxError("불완전한 데이터: 이름 없음"); // (*)
  }

  console.log( user.name );

} catch(e) {
    console.log(e.name)//SyntaxError
  console.log( "JSON Error: " + e.message ); // JSON Error: 불완전한 데이터: 이름 없음
}
```

즉 SyntexError의 error.message를 바꿔준다. 

## 에러 다시 던지기 
``` jsx
let json = '{ "age": 30 }'; // 불완전한 데이터

try {
  user = JSON.parse(json); // <-- user 앞에 let을 붙이는 걸 잊었네요.

  // ...
} catch(err) {
  alert("JSON Error: " + err); // JSON Error: ReferenceError: user is not defined
  // (실제론 JSON Error가 아닙니다.)
}
```

위에 에러는 사실 Json에러가 아닌다. 왜 에러 종류와 관계없이 동일한 방식으로 에러를 처리하지?

catch는 알고 에러만 처리하고 나머지는 다시 던지기!

1. catch가 모든 에러를 받는다. 
2. catch(err){...}블록 안에서 여러 객체 err를 분석
3. 만약 에러 처리 방법을 모르면 throw err 한다. 

``` jsx
let json = '{ "age": 30 }'; // 불완전한 데이터
try {

  let user = JSON.parse(json);

  if (!user.name) {
    throw new SyntaxError("불완전한 데이터: 이름 없음");
  }

  blabla(); // 예상치 못한 에러

  alert( user.name );

} catch(e) {

  if (e instanceof SyntaxError) {
    alert( "JSON Error: " + e.message );
  } else {
    throw e; // 에러 다시 던지기 (*)
  }

}
```

## try..catch..finally
finally 
- 에러가 없는 경우: try 실행이 끝난 후
- 에러가 있는 경우: catch 실행이 끝난 후 

``` jsx
try {
   ... 코드를 실행 ...
} catch(e) {
   ... 에러 핸들링 ...
} finally {
   ... 항상 실행 ...
}
```

``` jsx
try {
  alert( 'try 블록 시작' );
  if (confirm('에러를 만드시겠습니까?')) 이상한_코드();
} catch (e) {
  alert( 'catch' );
} finally {
  alert( 'finally' );
}
```

## 전역 catch
try..catch바깥에서 치명적인 에러가 발생해 스크립트가 죽었다..

대체 방법
window.onerror
``` jsx
window.onerror = function(message, url, line, col, error) {
  // ...
};
```



